Workbook

Sheet Premissas
A1: Projeto Implementado — Premissas e Fontes
A2: Motiva · Manutenção Preditiva das PSD · Dimensionamento de produção · 12 meses
A3: Todas as premissas ficam nesta aba. Alterar aqui recalcula as demais.
A5: Amarelo = premissa de entrada (editável)
A6: Cinza = calculado por fórmula (não editar)
A8: Câmbio e escala
A9: Cotação do dólar comercial | B9: 5.1 | C9: R$/US$ | D9: Cotação comercial de mercado · consultada em 09/09/2026
A10: Portas de plataforma monitoradas | B10: 528 | C10: portas | D10: Informado pela Motiva
A12: Mão de obra
A13: Salário dev Full-Stack Pleno | B13: 12000 | C13: R$/mês | D13: Faixa R$ 9.550-15.900 · Guia Salarial 2026 Robert Half
A14: Número de desenvolvedores | B14: 2 | C14: pessoas
A15: Duração da produtização | B15: 2.5 | C15: meses | D15: Produtização, integração com sistemas de origem, homologação e pipeline de deploy
A16: Fator de encargos CLT | B16: 1.8 | C16: x salário | D16: INSS 20%, FGTS 8%, RAT, Sistema S, 13o e férias · Lucro Presumido/Real
A18: Sustentação e retreinamento
A19: Horas de sustentação por mês | B19: 16 | C19: horas/mês | D19: 4 h/semana · sistema em produção com pipeline de dados e 3.360 alertas/ano
A20: Valor da hora de sustentação | B20: 70 | C20: R$/hora
A21: Ciclos de retreinamento por ano | B21: 4 | C21: ciclos/ano | D21: Retreinamento trimestral para conter degradação do modelo
A22: Horas por ciclo de retreinamento | B22: 40 | C22: horas/ciclo
A23: Valor da hora de retreinamento | B23: 90 | C23: R$/hora | D23: Perfil de cientista de dados, acima do valor-hora de sustentação
A25: Segurança
A26: Pentest e revisão de segurança | B26: 25000 | C26: R$, único | D26: Estimativa a cotar · exigência usual para sistema em concessionária
A28: Frontend
A29: Vercel Pro | B29: 20 | C29: US$/mês | D29: Preço por membro · página oficial de planos da Vercel
A30: Assentos Vercel | B30: 3 | C30: membros
A32: Azure SQL Database — preços públicos
A33: Produção — GP 4 vCore com redundância de zona | B33: 1000 | C33: US$/mês | D33: GP 4 vCore = US$ 730/mês; redundância de zona eleva para = US$ 1.000/mês
A34: Homologação — GP 2 vCore | B34: 365 | C34: US$/mês
A35: Desenvolvimento — serverless | B35: 50 | C35: US$/mês
A36: Desconto de reserva de 1 ano | B36: 0.33 | C36: sobre compute | D36: Reserva de 1 ano no General Purpose economiza = 33% sobre o pagamento por uso
A37: Armazenamento de produção | B37: 500 | C37: GB
A38: Preço do armazenamento (zone-redundant) | B38: 0.18 | C38: US$/GB/mês | D38: US$ 0,12 local · US$ 0,18 zona · US$ 0,24 geográfico
A39: Armazenamento de backup | B39: 1000 | C39: GB
A40: Preço do backup | B40: 0.12 | C40: US$/GB/mês
A42: OpenShift — preços ROSA e infraestrutura AWS
A43: Taxa de cluster ROSA | B43: 263 | C43: US$/ano | D43: US$ 0,03/hora · preços públicos Red Hat OpenShift Service on AWS
A44: Worker node 4 vCPU, reserva de 1 ano | B44: 998 | C44: US$/ano | D44: US$ 0,114 por 4vCPU/hora reservado · contra US$ 0,171 sob demanda
A45: Instância EC2 grande (4 vCPU) | B45: 1200 | C45: US$/ano | D45: Estimativa a cotar · classe m5.xlarge reservada 1 ano
A46: Instância EC2 média (2 vCPU) | B46: 600 | C46: US$/ano | D46: Estimativa a cotar · classe m5.large reservada 1 ano
A47: Preço do disco EBS | B47: 0.08 | C47: US$/GB/mês
A48: NAT gateway | B48: 394.2 | C48: US$/ano cada | D48: US$ 0,045/hora x 8.760 horas
...

Sheet Infraestrutura
A1: Dimensionamento de Infraestrutura
A2: Um cluster ROSA exige 3 nós de control plane, 2 a 3 de infraestrutura e no mínimo 2 workers (3 em multi-AZ).
A3: Zona única não é recomendada para produção. Daí os dois clusters: produção multi-AZ e não-produção.
A5: 1. Cluster OpenShift — produção (multi-AZ)
A6: Componente | B6: Qtd | C6: Preço unitário | D6: Custo anual US$ | E6: Observação
A7: Taxa de cluster ROSA | B7: 1 | C7: =Premissas!$B$43 -> 263 | D7: =B7*C7 -> 263 | E7: Taxa de gerenciamento Red Hat
A8: Worker nodes — licença ROSA | B8: 3 | C8: =Premissas!$B$44 -> 998 | D8: =B8*C8 -> 2994 | E8: Mínimo de 3 workers em multi-AZ
A9: Control plane — instâncias EC2 | B9: 3 | C9: =Premissas!$B$45 -> 1200 | D9: =B9*C9 -> 3600 | E9: Três nós obrigatórios por cluster
A10: Infra nodes — instâncias EC2 | B10: 3 | C10: =Premissas!$B$46 -> 600 | D10: =B10*C10 -> 1800 | E10: Registry, router e monitoramento
A11: Worker nodes — instâncias EC2 | B11: 3 | C11: =Premissas!$B$45 -> 1200 | D11: =B11*C11 -> 3600 | E11: Infraestrutura sob a licença ROSA
A12: Discos EBS (200 GB x 9 nós x 12 meses) | B12: 21600 | C12: =Premissas!$B$47 -> 0.08 | D12: =B12*C12 -> 1728 | E12: GB-mês x preço
A13: NAT gateway (1 por zona) | B13: 3 | C13: =Premissas!$B$48 -> 394.2 | D13: =B13*C13 -> 1182.6 | E13: Três zonas de disponibilidade
A14: Load balancers | B14: 2 | C14: =Premissas!$B$49 -> 197.1 | D14: =B14*C14 -> 394.2 | E14: API e router
A15: Transferência de dados | B15: 1 | C15: =Premissas!$B$50 -> 500 | D15: =B15*C15 -> 500 | E15: Estimativa anual
A16: SUBTOTAL — CLUSTER DE PRODUÇÃO | D16: =SUM(D7:D15) -> 16061.8
A18: 2. Cluster OpenShift — desenvolvimento e homologação (AZ única)
A19: Componente | B19: Qtd | C19: Preço unitário | D19: Custo anual US$ | E19: Observação
A20: Taxa de cluster ROSA | B20: 1 | C20: =Premissas!$B$43 -> 263 | D20: =B20*C20 -> 263 | E20: Taxa de gerenciamento Red Hat
A21: Worker nodes — licença ROSA | B21: 2 | C21: =Premissas!$B$44 -> 998 | D21: =B21*C21 -> 1996 | E21: Mínimo de 2 workers em zona única
A22: Control plane — instâncias EC2 | B22: 3 | C22: =Premissas!$B$46 -> 600 | D22: =B22*C22 -> 1800 | E22: Três nós obrigatórios, classe menor
A23: Infra nodes — instâncias EC2 | B23: 2 | C23: =Premissas!$B$46 -> 600 | D23: =B23*C23 -> 1200 | E23: Mínimo de dois nós de infraestrutura
A24: Worker nodes — instâncias EC2 | B24: 2 | C24: =Premissas!$B$45 -> 1200 | D24: =B24*C24 -> 2400 | E24: Infraestrutura sob a licença ROSA
A25: Discos EBS (100 GB x 7 nós x 12 meses) | B25: 8400 | C25: =Premissas!$B$47 -> 0.08 | D25: =B25*C25 -> 672 | E25: GB-mês x preço
A26: NAT gateway | B26: 1 | C26: =Premissas!$B$48 -> 394.2 | D26: =B26*C26 -> 394.2 | E26: Zona única
A27: Load balancer | B27: 1 | C27: =Premissas!$B$49 -> 197.1 | D27: =B27*C27 -> 197.1 | E27: Router
A28: SUBTOTAL — CLUSTER DE NÃO-PRODUÇÃO | D28: =SUM(D20:D27) -> 8922.3
A30: 3. Azure SQL Database
A31: Componente | B31: Meses | C31: Preço mensal | D31: Custo anual US$ | E31: Observação
A32: Produção — compute com reserva de 1 ano | B32: 12 | C32: =Premissas!$B$33*(1-Premissas!$B$36) -> 670 | D32: =B32*C32 -> 8040 | E32: GP 4 vCore com redundância de zona
A33: Homologação — compute com reserva | B33: 12 | C33: =Premissas!$B$34*(1-Premissas!$B$36) -> 244.55 | D33: =B33*C33 -> 2934.6 | E33: GP 2 vCore
A34: Desenvolvimento — compute serverless | B34: 12 | C34: =Premissas!$B$35 -> 50 | D34: =B34*C34 -> 600 | E34: Sem reserva: consumo intermitente
A35: SUBTOTAL — COMPUTE (custo fixo) | D35: =SUM(D32:D34) -> 11574.6
A36: Armazenamento de dados | B36: =Premissas!$B$37*12 -> 6000 | C36: =Premissas!$B$38 -> 0.18 | D36: =B36*C36 -> 1080 | E36: GB x 12 meses x preço zone-redundant
A37: Armazenamento de backup | B37: =Premissas!$B$39*12 -> 12000 | C37: =Premissas!$B$40 -> 0.12 | D37: =B37*C37 -> 1440 | E37: Retenção para auditoria
A38: SUBTOTAL — ARMAZENAMENTO (custo variável) | D38: =SUM(D36:D37) -> 2520
A40: 4. Demais serviços
A41: Componente | B41: Qtd | C41: Preço unitário | D41: Custo anual US$ | E41: Observação
A42: Vercel Pro | B42: =Premissas!$B$30*12 -> 36 | C42: =Premissas!$B$29 -> 20 | D42: =B42*C42 -> 720 | E42: Assentos x 12 meses
A43: Observabilidade e APM | B43: 12 | C43: =Premissas!$B$53 -> 200 | D43: =B43*C43 -> 2400
A44: Suporte enterprise | C44: =Premissas!$B$54 -> 0.1 | D44: =(D16+D28+D35+D38+D43)*Premissas!$B$54 -> 4147.87 | E44: Percentual sobre o gasto de nuvem
...

Sheet Orçamento
A1: Orçamento do Projeto Implementado — 12 meses
A2: Calculado a partir das abas Premissas e Infraestrutura.
A4: 1. CAPEX — investimento inicial
A5: Item | B5: Valor | D5: Cálculo
A6: Produtização da aplicação (regime PJ) | B6: =Premissas!B13*Premissas!B15*Premissas!B14 -> 60000 | D6: Salário x 2,5 meses x 2 desenvolvedores
A7: Pentest e revisão de segurança | B7: =Premissas!B26 -> 25000
A8: TOTAL CAPEX | B8: =SUM(B6:B7) -> 85000
A10: 2. OPEX anual — custos fixos
A11: Item | B11: Valor anual | D11: Cálculo
A12: Sustentação da aplicação | B12: =Premissas!B19*Premissas!B20*12 -> 13440 | D12: Horas/mês x valor-hora x 12
A13: Retreinamento do modelo | B13: =Premissas!B21*Premissas!B22*Premissas!B23 -> 14400 | D13: Ciclos x horas por ciclo x valor-hora de cientista de dados
A14: Cluster OpenShift — produção | B14: =Infraestrutura!D48 -> 81915.18
A15: Cluster OpenShift — não-produção | B15: =Infraestrutura!D49 -> 45503.73
A16: Azure SQL — compute | B16: =Infraestrutura!D50 -> 59030.46
A17: Vercel Pro | B17: =Infraestrutura!D52 -> 3672
A18: Observabilidade e APM | B18: =Infraestrutura!D53 -> 12240
A19: Suporte enterprise | B19: =Infraestrutura!D54 -> 21154.137
A20: TOTAL OPEX FIXO | B20: =SUM(B12:B19) -> 251355.51
A22: 3. OPEX anual — custos variáveis
A23: Item | B23: Valor anual | C23: Por porta | D23: Cálculo
A24: Azure SQL — armazenamento e backup | B24: =Infraestrutura!D51 -> 12852 | C24: =B24/Premissas!B10 -> 24.340909 | D24: Escala com o volume de dados e, portanto, com as portas
A25: TOTAL OPEX VARIÁVEL | B25: =B24 -> 12852 | C25: =B25/Premissas!B10 -> 24.340909
A27: 4. Itens avaliados sem custo incremental
A28: Item | B28: Valor | D28: Justificativa
A29: Atualização e disponibilização dos dados | B29: 0 | D29: Rotina já executada por equipe contratada
A30: Validação operacional das previsões | B30: 0 | D30: Extensão de informações já analisadas
A31: Docker e bibliotecas open source | B31: 0 | D31: Licenciamento gratuito
A32: Adequação à LGPD | B32: 0 | D32: Dados operacionais de equipamento, sem dados pessoais
A33: Treinamento de usuários | B33: 0 | D33: Equipe já familiarizada com os indicadores
A35: 5. Consolidação
A36: Categoria | B36: Valor | C36: Participação
A37: CAPEX — investimento inicial | B37: =B8 -> 85000 | C37: =B37/$B$41 -> 0.24340828
A38: OPEX fixo anual | B38: =B20 -> 251355.51 | C38: =B38/$B$41 -> 0.71978838
A39: OPEX variável anual | B39: =B25 -> 12852 | C39: =B39/$B$41 -> 0.036803333
A40: OPEX total anual | B40: =B38+B39 -> 264207.51
A41: CUSTO TOTAL DO ANO 1 | B41: =B37+B40 -> 349207.51 | C41: =B41/$B$41 -> 1
A42: Custo recorrente a partir do ano 2 | B42: =B40 -> 264207.51 | D42: O CAPEX não se repete

Sheet Cronograma
A1: Cronograma de Desembolso — 12 meses
A2: Produtização distribuída nos 3 primeiros meses. Retreinamento nos meses 3, 6, 9 e 12.
A4: Mês | B4: Produtização | C4: Segurança | D4: Infraestrutura | E4: Sustentação | F4: Retreinamento | G4: Suporte | H4: Total do mês | I4: Acumulado
A5: 1 | B5: =Orçamento!$B$6/3 -> 20000 | C5: =0 -> 0 | D5: =(Orçamento!$B$14+Orçamento!$B$15+Orçamento!$B$16+Orçamento!$B$17+Orçamento!$B$18+Orçamento!$B$24)/12 -> 17934.447 | E5: =Orçamento!$B$12/12 -> 1120 | F5: =0 -> 0 | G5: =Orçamento!$B$19/12 -> 1762.8447 | H5: =SUM(B5:G5) -> 40817.292 | I5: =H5 -> 40817.292
A6: 2 | B6: =Orçamento!$B$6/3 -> 20000 | C6: =0 -> 0 | D6: =(Orçamento!$B$14+Orçamento!$B$15+Orçamento!$B$16+Orçamento!$B$17+Orçamento!$B$18+Orçamento!$B$24)/12 -> 17934.447 | E6: =Orçamento!$B$12/12 -> 1120 | F6: =0 -> 0 | G6: =Orçamento!$B$19/12 -> 1762.8447 | H6: =SUM(B6:G6) -> 40817.292 | I6: =I5+H6 -> 81634.584
A7: 3 | B7: =Orçamento!$B$6/3 -> 20000 | C7: =Orçamento!$B$7 -> 25000 | D7: =(Orçamento!$B$14+Orçamento!$B$15+Orçamento!$B$16+Orçamento!$B$17+Orçamento!$B$18+Orçamento!$B$24)/12 -> 17934.447 | E7: =Orçamento!$B$12/12 -> 1120 | F7: =Orçamento!$B$13/Premissas!$B$21 -> 3600 | G7: =Orçamento!$B$19/12 -> 1762.8447 | H7: =SUM(B7:G7) -> 69417.292 | I7: =I6+H7 -> 151051.88
A8: 4 | B8: =0 -> 0 | C8: =0 -> 0 | D8: =(Orçamento!$B$14+Orçamento!$B$15+Orçamento!$B$16+Orçamento!$B$17+Orçamento!$B$18+Orçamento!$B$24)/12 -> 17934.447 | E8: =Orçamento!$B$12/12 -> 1120 | F8: =0 -> 0 | G8: =Orçamento!$B$19/12 -> 1762.8447 | H8: =SUM(B8:G8) -> 20817.292 | I8: =I7+H8 -> 171869.17
A9: 5 | B9: =0 -> 0 | C9: =0 -> 0 | D9: =(Orçamento!$B$14+Orçamento!$B$15+Orçamento!$B$16+Orçamento!$B$17+Orçamento!$B$18+Orçamento!$B$24)/12 -> 17934.447 | E9: =Orçamento!$B$12/12 -> 1120 | F9: =0 -> 0 | G9: =Orçamento!$B$19/12 -> 1762.8447 | H9: =SUM(B9:G9) -> 20817.292 | I9: =I8+H9 -> 192686.46
A10: 6 | B10: =0 -> 0 | C10: =0 -> 0 | D10: =(Orçamento!$B$14+Orçamento!$B$15+Orçamento!$B$16+Orçamento!$B$17+Orçamento!$B$18+Orçamento!$B$24)/12 -> 17934.447 | E10: =Orçamento!$B$12/12 -> 1120 | F10: =Orçamento!$B$13/Premissas!$B$21 -> 3600 | G10: =Orçamento!$B$19/12 -> 1762.8447 | H10: =SUM(B10:G10) -> 24417.292 | I10: =I9+H10 -> 217103.75
A11: 7 | B11: =0 -> 0 | C11: =0 -> 0 | D11: =(Orçamento!$B$14+Orçamento!$B$15+Orçamento!$B$16+Orçamento!$B$17+Orçamento!$B$18+Orçamento!$B$24)/12 -> 17934.447 | E11: =Orçamento!$B$12/12 -> 1120 | F11: =0 -> 0 | G11: =Orçamento!$B$19/12 -> 1762.8447 | H11: =SUM(B11:G11) -> 20817.292 | I11: =I10+H11 -> 237921.05
A12: 8 | B12: =0 -> 0 | C12: =0 -> 0 | D12: =(Orçamento!$B$14+Orçamento!$B$15+Orçamento!$B$16+Orçamento!$B$17+Orçamento!$B$18+Orçamento!$B$24)/12 -> 17934.447 | E12: =Orçamento!$B$12/12 -> 1120 | F12: =0 -> 0 | G12: =Orçamento!$B$19/12 -> 1762.8447 | H12: =SUM(B12:G12) -> 20817.292 | I12: =I11+H12 -> 258738.34
A13: 9 | B13: =0 -> 0 | C13: =0 -> 0 | D13: =(Orçamento!$B$14+Orçamento!$B$15+Orçamento!$B$16+Orçamento!$B$17+Orçamento!$B$18+Orçamento!$B$24)/12 -> 17934.447 | E13: =Orçamento!$B$12/12 -> 1120 | F13: =Orçamento!$B$13/Premissas!$B$21 -> 3600 | G13: =Orçamento!$B$19/12 -> 1762.8447 | H13: =SUM(B13:G13) -> 24417.292 | I13: =I12+H13 -> 283155.63
A14: 10 | B14: =0 -> 0 | C14: =0 -> 0 | D14: =(Orçamento!$B$14+Orçamento!$B$15+Orçamento!$B$16+Orçamento!$B$17+Orçamento!$B$18+Orçamento!$B$24)/12 -> 17934.447 | E14: =Orçamento!$B$12/12 -> 1120 | F14: =0 -> 0 | G14: =Orçamento!$B$19/12 -> 1762.8447 | H14: =SUM(B14:G14) -> 20817.292 | I14: =I13+H14 -> 303972.92
A15: 11 | B15: =0 -> 0 | C15: =0 -> 0 | D15: =(Orçamento!$B$14+Orçamento!$B$15+Orçamento!$B$16+Orçamento!$B$17+Orçamento!$B$18+Orçamento!$B$24)/12 -> 17934.447 | E15: =Orçamento!$B$12/12 -> 1120 | F15: =0 -> 0 | G15: =Orçamento!$B$19/12 -> 1762.8447 | H15: =SUM(B15:G15) -> 20817.292 | I15: =I14+H15 -> 324790.21
A16: 12 | B16: =0 -> 0 | C16: =0 -> 0 | D16: =(Orçamento!$B$14+Orçamento!$B$15+Orçamento!$B$16+Orçamento!$B$17+Orçamento!$B$18+Orçamento!$B$24)/12 -> 17934.447 | E16: =Orçamento!$B$12/12 -> 1120 | F16: =Orçamento!$B$13/Premissas!$B$21 -> 3600 | G16: =Orçamento!$B$19/12 -> 1762.8447 | H16: =SUM(B16:G16) -> 24417.292 | I16: =I15+H16 -> 349207.51
A17: ="Total" -> Total | B17: =SUM(B5:B16) -> 60000 | C17: =SUM(C5:C16) -> 25000 | D17: =SUM(D5:D16) -> 215213.37 | E17: =SUM(E5:E16) -> 13440 | F17: =SUM(F5:F16) -> 14400 | G17: =SUM(G5:G16) -> 21154.137 | H17: =SUM(H5:H16) -> 349207.51
A19: Concentração do desembolso
A20: Meses 1 a 3 — implantação | B20: =SUM(H5:H7) -> 151051.88 | C20: =SUM(H5:H7)/H17 -> 0.43255621
A21: Meses 4 a 12 — operação | B21: =SUM(H8:H16) -> 198155.63 | C21: =SUM(H8:H16)/H17 -> 0.56744379
A22: Custo mensal em regime | B22: =H8 -> 20817.292

Sheet Cenários
A1: Cenários de Contingência e Sensibilidade
A3: 1. Margens percentuais
A4: Cenário | B4: Custo em 12 meses | C4: Variação | D4: Critério
A5: Base | B5: =Orçamento!B41 -> 349207.51 | C5: =B5/$B$5-1 -> 0 | D5: Estimativa central do dimensionamento de produção
A6: Conservador | B6: =$B$5*(1+Premissas!B57) -> 366667.88 | C6: =B6/$B$5-1 -> 0.05
A7: Pior caso | B7: =$B$5*(1+Premissas!B58) -> 384128.26 | C7: =B7/$B$5-1 -> 0.1
A9: 2. Regime de contratação da mão de obra
A10: Categoria | B10: Regime PJ (base) | C10: Regime CLT
A11: CAPEX — produtização | B11: =Orçamento!B6 -> 60000 | C11: =Orçamento!B6*Premissas!B16 -> 108000
A12: CAPEX — segurança | B12: =Orçamento!B7 -> 25000 | C12: =Orçamento!B7 -> 25000
A13: OPEX total anual | B13: =Orçamento!B40 -> 264207.51 | C13: =Orçamento!B40 -> 264207.51
A14: TOTAL EM 12 MESES | B14: =SUM(B11:B13) -> 349207.51 | C14: =SUM(C11:C13) -> 397207.51
A15: Diferença | C15: =C14-B14 -> 48000
A17: 3. Sensibilidade cambial
A18: Toda a infraestrutura é denominada em dólar. Mão de obra e segurança são em real.
A19: Cotação (R$/US$) | B19: Infraestrutura em R$ | C19: Custo total ano 1 | D19: Variação sobre a base
A20: 4.6 | B20: =Infraestrutura!$C$55*A20 -> 213194.22 | C20: =Orçamento!$B$41-Infraestrutura!$D$55+B20 -> 326034.22 | D20: =C20/Orçamento!$B$41-1 -> -0.066359642
A21: 5.1 | B21: =Infraestrutura!$C$55*A21 -> 236367.51 | C21: =Orçamento!$B$41-Infraestrutura!$D$55+B21 -> 349207.51 | D21: =C21/Orçamento!$B$41-1 -> 0
A22: 5.6 | B22: =Infraestrutura!$C$55*A22 -> 259540.79 | C22: =Orçamento!$B$41-Infraestrutura!$D$55+B22 -> 372380.79 | D22: =C22/Orçamento!$B$41-1 -> 0.066359642
A23: 6.1 | B23: =Infraestrutura!$C$55*A23 -> 282714.08 | C23: =Orçamento!$B$41-Infraestrutura!$D$55+B23 -> 395554.08 | D23: =C23/Orçamento!$B$41-1 -> 0.13271928
A25: 4. Sensibilidade ao número de ambientes
A26: O cluster de não-produção é a linha mais facilmente questionável do orçamento.
A27: Configuração | B27: Custo em 12 meses | C27: Variação
A28: Com cluster de não-produção (base) | B28: =Orçamento!B41 -> 349207.51 | C28: =B28/$B$28-1 -> 0
A29: Sem cluster de não-produção | B29: =Orçamento!B41-Orçamento!B15 -> 303703.78 | C29: =B29/$B$28-1 -> -0.1303057 | D29: Não recomendado: implica testar em produção
A31: 5. Resumo
A32: Cenário | B32: Custo em 12 meses
A33: Base | B33: =B5 -> 349207.51
A34: Conservador | B34: =B6 -> 366667.88
A35: Pior caso | B35: =B7 -> 384128.26
A36: Contratação CLT | B36: =C14 -> 397207.51
A37: Custo recorrente do ano 2 | B37: =Orçamento!B42 -> 264207.51
