Workbook

Sheet Modelo
A1: Retorno Econômico — Margem de Contribuição, Ponto de Equilíbrio, ROI e Payback
A2: Motiva · Manutenção Preditiva das PSD · Cenário do projeto implementado, 12 meses
A3: ATENÇÃO: os campos em vermelho dependem de dados ainda não fornecidos pela Motiva. Enquanto estiverem vazios, os indicadores da seção 5 não são calculados.
A5: Amarelo = premissa de entrada (editável)
A6: Cinza = calculado por fórmula (não editar)
A7: Vermelho = parâmetro pendente de fornecimento pela Motiva
A9: 1. Premissas operacionais
A10: Portas de plataforma monitoradas | B10: 528 | C10: portas | D10: Informado pela Motiva
A11: Ocorrências corretivas por mês | B11: 140 | C11: falhas/mês | D11: Informado pela Motiva
A12: Ocorrências corretivas por ano | B12: =B11*12 -> 1680 | C12: falhas/ano
A13: Falhas corretivas por porta ao ano | B13: =B12/B10 -> 3.1818182 | C13: falhas/porta/ano
A15: 2. Desempenho esperado do modelo
A16: Recall esperado | B16: 0.6 | C16: % das falhas | D16: Teto estimado pelo grupo pela qualidade das bases — não é métrica medida
A17: Precisão esperada | B17: 0.3 | C17: % dos alertas | D17: Teto estimado pelo grupo pela qualidade das bases — não é métrica medida
A18: Falhas antecipadas (verdadeiros positivos) | B18: =B12*B16 -> 1008 | C18: falhas/ano
A19: Total de alertas emitidos | B19: =B18/B17 -> 3360 | C19: alertas/ano
A20: Alertas improdutivos (falsos positivos) | B20: =B19-B18 -> 2352 | C20: alertas/ano
A21: Falsos positivos por dia útil | B21: =B20/252 -> 9.3333333 | C21: alertas/dia
A22: Razão falsos / verdadeiros positivos | B22: =B20/B18 -> 2.3333333 | C22: alertas por falha
A23: Falhas não antecipadas | B23: =B12-B18 -> 672 | C23: falhas/ano
A25: 3. Estrutura de custos
A26: CAPEX — investimento inicial | B26: 18000 | D26: Planilha 2 · aba Orçamento · aprimoramento e implantação
A27: OPEX fixo anual | B27: 11015.1 | D27: Planilha 2 · Vercel + Red Hat + sustentação
A28: OPEX variável anual | B28: 1500 | D28: Planilha 2 · reserva do Azure SQL Database
A29: OPEX total anual | B29: =B27+B28 -> 12515.1
A30: Custo total do ano 1 | B30: =B26+B29 -> 30515.1
A31: Custo variável por porta ao ano | B31: =B28/B10 -> 2.8409091
A33: 4. Parâmetros monetários pendentes
A34: Preencher quando a Motiva fornecer os dados. Os indicadores da seção 5 são calculados automaticamente.
A35: Custo médio de uma ordem ZM01 fechada | D35: Motiva · sistema de manutenção · peça + mão de obra
A36: Custo médio de uma ZM02/ZM03 equivalente | D36: Motiva · sistema de manutenção · intervenção programada
A37: Custo médio de indisponibilidade por falha | D37: Motiva · registro de penalidades por causa raiz
A38: E — Economia por falha evitada | B38: =IF(COUNT(B35:B37)<3,"",(B35-B36)+B37) | D38: (ZM01 − ZM02/ZM03) + indisponibilidade. A subtração é essencial: se a peça é trocada
D39: nos dois regimes, a economia é o diferencial da intervenção, não o valor da peça.
A40: Cf — Custo de atender um alerta falso | D40: Motiva · tempo de verificação × custo-hora da equipe
A41: A — Taxa de troca efetiva | B41: 1 | C41: % das previsões | D41: Proporção das previsões corretas que de fato evitam a ocorrência. Base: 100%
A43: 5. Resultados — MC, ponto de equilíbrio, ROI e payback
A44: Falhas evitadas por ano | B44: =B18*B41 -> 1008 | C44: falhas/ano
A45: Redução de falhas | B45: =B44/B12 -> 0.6 | C45: % do total
A46: Economia bruta anual | B46: =IF($B$38="","",B44*$B$38) | C46: R$/ano
...

Sheet Simulação
A1: Simulação — comportamento do modelo sob hipóteses de E
A2: Nenhuma linha desta aba é projeção. O parâmetro E não é conhecido. Cada linha mostra o que o modelo produziria SE E assumisse o valor indicado.
A3: Cf considerado igual a zero nesta aba, conforme o cenário-base. A sensibilidade a Cf está na seção 2.
A5: 1. Indicadores em função de E
A6: Hipótese de E (R$/falha) | B6: Economia anual | C6: Economia por porta | D6: MC unitária | E6: Ponto de equilíbrio (portas) | F6: Resultado anual | G6: ROI ano 1 | H6: Payback (meses)
A7: 100 | B7: =A7*Modelo!$B$44 -> 100800 | C7: =B7/Modelo!$B$10 -> 190.90909 | D7: =C7-Modelo!$B$31 -> 188.06818 | E7: =Modelo!$B$27/D7 -> 58.569716 | F7: =B7-Modelo!$B$29 -> 88284.9 | G7: =(F7-Modelo!$B$26)/Modelo!$B$26 -> 3.9047167 | H7: =Modelo!$B$26/F7*12 -> 2.4466245
A8: 300 | B8: =A8*Modelo!$B$44 -> 302400 | C8: =B8/Modelo!$B$10 -> 572.72727 | D8: =C8-Modelo!$B$31 -> 569.88636 | E8: =Modelo!$B$27/D8 -> 19.32859 | F8: =B8-Modelo!$B$29 -> 289884.9 | G8: =(F8-Modelo!$B$26)/Modelo!$B$26 -> 15.104717 | H8: =Modelo!$B$26/F8*12 -> 0.74512332
A9: 500 | B9: =A9*Modelo!$B$44 -> 504000 | C9: =B9/Modelo!$B$10 -> 954.54545 | D9: =C9-Modelo!$B$31 -> 951.70455 | E9: =Modelo!$B$27/D9 -> 11.574075 | F9: =B9-Modelo!$B$29 -> 491484.9 | G9: =(F9-Modelo!$B$26)/Modelo!$B$26 -> 26.304717 | H9: =Modelo!$B$26/F9*12 -> 0.43948451
A10: 1000 | B10: =A10*Modelo!$B$44 -> 1008000 | C10: =B10/Modelo!$B$10 -> 1909.0909 | D10: =C10-Modelo!$B$31 -> 1906.25 | E10: =Modelo!$B$27/D10 -> 5.7784131 | F10: =B10-Modelo!$B$29 -> 995484.9 | G10: =(F10-Modelo!$B$26)/Modelo!$B$26 -> 54.304717 | H10: =Modelo!$B$26/F10*12 -> 0.21697968
A11: 2000 | B11: =A11*Modelo!$B$44 -> 2016000 | C11: =B11/Modelo!$B$10 -> 3818.1818 | D11: =C11-Modelo!$B$31 -> 3815.3409 | E11: =Modelo!$B$27/D11 -> 2.8870552 | F11: =B11-Modelo!$B$29 -> 2003484.9 | G11: =(F11-Modelo!$B$26)/Modelo!$B$26 -> 110.30472 | H11: =Modelo!$B$26/F11*12 -> 0.10781214
A13: O índice de margem de contribuição supera 98% em todas as faixas: o custo variável de R$ 2,84 por porta
A14: ao ano é desprezível diante de qualquer economia unitária plausível. É um projeto essencialmente de custo fixo.
A16: 2. Sensibilidade ao custo dos alertas improdutivos (Cf)
A17: Assumindo E = R$ 1.000 por falha evitada. O projeto deixa de gerar economia líquida quando E < 2,33 × Cf.
A18: Cf (R$/alerta) | B18: Economia bruta | C18: Custo dos falsos positivos | D18: Economia líquida | E18: Resultado anual | F18: Situação
A19: 0 | B19: =1000*Modelo!$B$44 -> 1008000 | C19: =A19*Modelo!$B$20 -> 0 | D19: =B19-C19 -> 1008000 | E19: =D19-Modelo!$B$29 -> 995484.9 | F19: =IF(E19>0,"Viável","Inviável") -> Viável
A20: 100 | B20: =1000*Modelo!$B$44 -> 1008000 | C20: =A20*Modelo!$B$20 -> 235200 | D20: =B20-C20 -> 772800 | E20: =D20-Modelo!$B$29 -> 760284.9 | F20: =IF(E20>0,"Viável","Inviável") -> Viável
A21: 200 | B21: =1000*Modelo!$B$44 -> 1008000 | C21: =A21*Modelo!$B$20 -> 470400 | D21: =B21-C21 -> 537600 | E21: =D21-Modelo!$B$29 -> 525084.9 | F21: =IF(E21>0,"Viável","Inviável") -> Viável
A22: 300 | B22: =1000*Modelo!$B$44 -> 1008000 | C22: =A22*Modelo!$B$20 -> 705600 | D22: =B22-C22 -> 302400 | E22: =D22-Modelo!$B$29 -> 289884.9 | F22: =IF(E22>0,"Viável","Inviável") -> Viável
A23: 429 | B23: =1000*Modelo!$B$44 -> 1008000 | C23: =A23*Modelo!$B$20 -> 1009008 | D23: =B23-C23 -> -1008 | E23: =D23-Modelo!$B$29 -> -13523.1 | F23: =IF(E23>0,"Viável","Inviável") -> Inviável
A24: 500 | B24: =1000*Modelo!$B$44 -> 1008000 | C24: =A24*Modelo!$B$20 -> 1176000 | D24: =B24-C24 -> -168000 | E24: =D24-Modelo!$B$29 -> -180515.1 | F24: =IF(E24>0,"Viável","Inviável") -> Inviável
A26: 3. Sensibilidade à taxa de troca efetiva (A)
A27: Mede o impacto da incerteza sobre a substituição de peças: nem toda previsão correta evita a ocorrência.
A28: Taxa de troca efetiva | B28: Falhas evitadas/ano | C28: Redução de falhas | D28: E mínimo — ano 1 | E28: E mínimo — ano 2
A29: 0.25 | B29: =Modelo!$B$18*A29 -> 252 | C29: =B29/Modelo!$B$12 -> 0.15 | D29: =Modelo!$B$30/B29 -> 121.09167 | E29: =Modelo!$B$29/B29 -> 49.663095
A30: 0.5 | B30: =Modelo!$B$18*A30 -> 504 | C30: =B30/Modelo!$B$12 -> 0.3 | D30: =Modelo!$B$30/B30 -> 60.545833 | E30: =Modelo!$B$29/B30 -> 24.831548
A31: 0.75 | B31: =Modelo!$B$18*A31 -> 756 | C31: =B31/Modelo!$B$12 -> 0.45 | D31: =Modelo!$B$30/B31 -> 40.363889 | E31: =Modelo!$B$29/B31 -> 16.554365
A32: 1 | B32: =Modelo!$B$18*A32 -> 1008 | C32: =B32/Modelo!$B$12 -> 0.6 | D32: =Modelo!$B$30/B32 -> 30.272917 | E32: =Modelo!$B$29/B32 -> 12.415774
A34: Mesmo no cenário mais pessimista, em que apenas uma em cada quatro previsões corretas evita de fato
A35: a falha, o limiar de viabilidade permanece baixo. A conclusão é robusta à incerteza sobre a troca de peças.
